[2015-10-16 09:19:45,538: WARNING/MainProcess] worker@omega014 ready.
[2015-10-16 09:24:42,225: ERROR/MainProcess] Unrecoverable error: ResponseError('MISCONF Redis is configured to save RDB snapshots, but is currently not able to persist on disk. Commands that may modify the data set are disabled. Please check Redis logs for details about the error.',)
Traceback (most recent call last):
  File "/cluster/home/mmunso01/envs/nidaba/lib/python2.7/site-packages/celery/worker/__init__.py", line 206, in start
    self.blueprint.start(self)
  File "/cluster/home/mmunso01/envs/nidaba/lib/python2.7/site-packages/celery/bootsteps.py", line 123, in start
    step.start(parent)
  File "/cluster/home/mmunso01/envs/nidaba/lib/python2.7/site-packages/celery/bootsteps.py", line 374, in start
    return self.obj.start()
  File "/cluster/home/mmunso01/envs/nidaba/lib/python2.7/site-packages/celery/worker/consumer.py", line 278, in start
    blueprint.start(self)
  File "/cluster/home/mmunso01/envs/nidaba/lib/python2.7/site-packages/celery/bootsteps.py", line 123, in start
    step.start(parent)
  File "/cluster/home/mmunso01/envs/nidaba/lib/python2.7/site-packages/celery/worker/consumer.py", line 821, in start
    c.loop(*c.loop_args())
  File "/cluster/home/mmunso01/envs/nidaba/lib/python2.7/site-packages/celery/worker/loops.py", line 70, in asynloop
    next(loop)
  File "/cluster/home/mmunso01/envs/nidaba/lib/python2.7/site-packages/kombu/async/hub.py", line 324, in create_loop
    cb(*cbargs)
  File "/cluster/home/mmunso01/envs/nidaba/lib/python2.7/site-packages/kombu/transport/redis.py", line 950, in on_readable
    item = self.cycle.on_readable(fileno)
  File "/cluster/home/mmunso01/envs/nidaba/lib/python2.7/site-packages/kombu/transport/redis.py", line 322, in on_readable
    return chan.handlers[type]()
  File "/cluster/home/mmunso01/envs/nidaba/lib/python2.7/site-packages/kombu/transport/redis.py", line 619, in _brpop_read
    **options)
  File "/cluster/home/mmunso01/envs/nidaba/lib/python2.7/site-packages/redis/client.py", line 577, in parse_response
    response = connection.read_response()
  File "/cluster/home/mmunso01/envs/nidaba/lib/python2.7/site-packages/redis/connection.py", line 574, in read_response
    raise response
ResponseError: MISCONF Redis is configured to save RDB snapshots, but is currently not able to persist on disk. Commands that may modify the data set are disabled. Please check Redis logs for details about the error.
[2015-10-16 09:24:50,937: WARNING/Worker-28] /cluster/home/mmunso01/envs/nidaba/lib/python2.7/site-packages/celery/app/trace.py:365: RuntimeWarning: Exception raised outside body: ResponseError(u'Command # 1 (SETEX celery-task-meta-a1674a8e-6461-46fa-a8d9-68664fb9fbf2 86400 {"status": "FAILURE", "traceback": "Traceback (most recent call last):\\n  File \\"/cluster/home/mmunso01/envs/nidaba/lib/python2.7/site-packages/celery/app/trace.py\\", line 240, in trace_task\\n    R = retval = fun(*args, **kwargs)\\n  File \\"/cluster/home/mmunso01/envs/nidaba/lib/python2.7/site-packages/nidaba/tasks/helper.py\\", line 92, in __call__\\n    _redis_set_atomically(batch_id, task_id, \'state\', \'SUCCESS\')\\n  File \\"/cluster/home/mmunso01/envs/nidaba/lib/python2.7/site-packages/nidaba/tasks/helper.py\\", line 32, in _redis_set_atomically\\n    pipe.execute()\\n  File \\"/cluster/home/mmunso01/envs/nidaba/lib/python2.7/site-packages/redis/client.py\\", line 2578, in execute\\n    return execute(conn, stack, raise_on_error)\\n  File \\"/cluster/home/mmunso01/envs/nidaba/lib/python2.7/site-packages/redis/client.py\\", line 2473, in _execute_transaction\\n    self.immediate_execute_command(\'DISCARD\')\\n  File \\"/cluster/home/mmunso01/envs/nidaba/lib/python2.7/site-packages/redis/client.py\\", line 2413, in immediate_execute_command\\n    return self.parse_response(conn, command_name, **options)\\n  File \\"/cluster/home/mmunso01/envs/nidaba/lib/python2.7/site-packages/redis/client.py\\", line 2536, in parse_response\\n    self, connection, command_name, **options)\\n  File \\"/cluster/home/mmunso01/envs/nidaba/lib/python2.7/site-packages/redis/client.py\\", line 577, in parse_response\\n    response = connection.read_response()\\n  File \\"/cluster/home/mmunso01/envs/nidaba/lib/python2.7/site-packages/redis/connection.py\\", line 574, in read_response\\n    raise response\\nResponseError: DISCARD without MULTI\\n", "result": {"exc_message": "DISCARD without MULTI", "exc_type": "ResponseError"}, "children": []}) of pipeline caused error: MISCONF Redis is configured to save RDB snapshots, but is currently not able to persist on disk. Commands that may modify the data set are disabled. Please check Redis logs for details about the error.',):
Traceback (most recent call last):
  File "/cluster/home/mmunso01/envs/nidaba/lib/python2.7/site-packages/celery/app/trace.py", line 253, in trace_task
    I, R, state, retval = on_error(task_request, exc, uuid)
  File "/cluster/home/mmunso01/envs/nidaba/lib/python2.7/site-packages/celery/app/trace.py", line 201, in on_error
    R = I.handle_error_state(task, eager=eager)
  File "/cluster/home/mmunso01/envs/nidaba/lib/python2.7/site-packages/celery/app/trace.py", line 85, in handle_error_state
    }[self.state](task, store_errors=store_errors)
  File "/cluster/home/mmunso01/envs/nidaba/lib/python2.7/site-packages/celery/app/trace.py", line 118, in handle_failure
    req.id, exc, einfo.traceback, request=req,
  File "/cluster/home/mmunso01/envs/nidaba/lib/python2.7/site-packages/celery/backends/base.py", line 121, in mark_as_failure
    traceback=traceback, request=request)
  File "/cluster/home/mmunso01/envs/nidaba/lib/python2.7/site-packages/celery/backends/base.py", line 256, in store_result
    request=request, **kwargs)
  File "/cluster/home/mmunso01/envs/nidaba/lib/python2.7/site-packages/celery/backends/base.py", line 490, in _store_result
    self.set(self.get_key_for_task(task_id), self.encode(meta))
  File "/cluster/home/mmunso01/envs/nidaba/lib/python2.7/site-packages/celery/backends/redis.py", line 160, in set
    return self.ensure(self._set, (key, value), **retry_policy)
  File "/cluster/home/mmunso01/envs/nidaba/lib/python2.7/site-packages/celery/backends/redis.py", line 149, in ensure
    **retry_policy
  File "/cluster/home/mmunso01/envs/nidaba/lib/python2.7/site-packages/kombu/utils/__init__.py", line 243, in retry_over_time
    return fun(*args, **kwargs)
  File "/cluster/home/mmunso01/envs/nidaba/lib/python2.7/site-packages/celery/backends/redis.py", line 169, in _set
    pipe.execute()
  File "/cluster/home/mmunso01/envs/nidaba/lib/python2.7/site-packages/redis/client.py", line 2578, in execute
    return execute(conn, stack, raise_on_error)
  File "/cluster/home/mmunso01/envs/nidaba/lib/python2.7/site-packages/redis/client.py", line 2475, in _execute_transaction
    raise errors[0][1]
ResponseError: Command # 1 (SETEX celery-task-meta-a1674a8e-6461-46fa-a8d9-68664fb9fbf2 86400 {"status": "FAILURE", "traceback": "Traceback (most recent call last):\n  File \"/cluster/home/mmunso01/envs/nidaba/lib/python2.7/site-packages/celery/app/trace.py\", line 240, in trace_task\n    R = retval = fun(*args, **kwargs)\n  File \"/cluster/home/mmunso01/envs/nidaba/lib/python2.7/site-packages/nidaba/tasks/helper.py\", line 92, in __call__\n    _redis_set_atomically(batch_id, task_id, 'state', 'SUCCESS')\n  File \"/cluster/home/mmunso01/envs/nidaba/lib/python2.7/site-packages/nidaba/tasks/helper.py\", line 32, in _redis_set_atomically\n    pipe.execute()\n  File \"/cluster/home/mmunso01/envs/nidaba/lib/python2.7/site-packages/redis/client.py\", line 2578, in execute\n    return execute(conn, stack, raise_on_error)\n  File \"/cluster/home/mmunso01/envs/nidaba/lib/python2.7/site-packages/redis/client.py\", line 2473, in _execute_transaction\n    self.immediate_execute_command('DISCARD')\n  File \"/cluster/home/mmunso01/envs/nidaba/lib/python2.7/site-packages/redis/client.py\", line 2413, in immediate_execute_command\n    return self.parse_response(conn, command_name, **options)\n  File \"/cluster/home/mmunso01/envs/nidaba/lib/python2.7/site-packages/redis/client.py\", line 2536, in parse_response\n    self, connection, command_name, **options)\n  File \"/cluster/home/mmunso01/envs/nidaba/lib/python2.7/site-packages/redis/client.py\", line 577, in parse_response\n    response = connection.read_response()\n  File \"/cluster/home/mmunso01/envs/nidaba/lib/python2.7/site-packages/redis/connection.py\", line 574, in read_response\n    raise response\nResponseError: DISCARD without MULTI\n", "result": {"exc_message": "DISCARD without MULTI", "exc_type": "ResponseError"}, "children": []}) of pipeline caused error: MISCONF Redis is configured to save RDB snapshots, but is currently not able to persist on disk. Commands that may modify the data set are disabled. Please check Redis logs for details about the error.

  exc, exc_info.traceback)))
[2015-10-16 09:24:50,952: WARNING/Worker-28] /cluster/home/mmunso01/envs/nidaba/lib/python2.7/site-packages/celery/app/trace.py:365: RuntimeWarning: Exception raised outside body: ResponseError(u'Command # 1 (SETEX celery-task-meta-39d21efc-8966-40bb-b367-a6e871475d6b 86400 {"status": "FAILURE", "traceback": "Traceback (most recent call last):\\n  File \\"/cluster/home/mmunso01/envs/nidaba/lib/python2.7/site-packages/celery/app/trace.py\\", line 240, in trace_task\\n    R = retval = fun(*args, **kwargs)\\n  File \\"/cluster/home/mmunso01/envs/nidaba/lib/python2.7/site-packages/nidaba/tasks/helper.py\\", line 89, in __call__\\n    _redis_set_atomically(batch_id, task_id, \'errors\', (nkwargs, e.message))\\n  File \\"/cluster/home/mmunso01/envs/nidaba/lib/python2.7/site-packages/nidaba/tasks/helper.py\\", line 32, in _redis_set_atomically\\n    pipe.execute()\\n  File \\"/cluster/home/mmunso01/envs/nidaba/lib/python2.7/site-packages/redis/client.py\\", line 2578, in execute\\n    return execute(conn, stack, raise_on_error)\\n  File \\"/cluster/home/mmunso01/envs/nidaba/lib/python2.7/site-packages/redis/client.py\\", line 2473, in _execute_transaction\\n    self.immediate_execute_command(\'DISCARD\')\\n  File \\"/cluster/home/mmunso01/envs/nidaba/lib/python2.7/site-packages/redis/client.py\\", line 2413, in immediate_execute_command\\n    return self.parse_response(conn, command_name, **options)\\n  File \\"/cluster/home/mmunso01/envs/nidaba/lib/python2.7/site-packages/redis/client.py\\", line 2536, in parse_response\\n    self, connection, command_name, **options)\\n  File \\"/cluster/home/mmunso01/envs/nidaba/lib/python2.7/site-packages/redis/client.py\\", line 577, in parse_response\\n    response = connection.read_response()\\n  File \\"/cluster/home/mmunso01/envs/nidaba/lib/python2.7/site-packages/redis/connection.py\\", line 574, in read_response\\n    raise response\\nResponseError: DISCARD without MULTI\\n", "result": {"exc_message": "DISCARD without MULTI", "exc_type": "ResponseError"}, "children": []}) of pipeline caused error: MISCONF Redis is configured to save RDB snapshots, but is currently not able to persist on disk. Commands that may modify the data set are disabled. Please check Redis logs for details about the error.',):
Traceback (most recent call last):
  File "/cluster/home/mmunso01/envs/nidaba/lib/python2.7/site-packages/celery/app/trace.py", line 253, in trace_task
    I, R, state, retval = on_error(task_request, exc, uuid)
  File "/cluster/home/mmunso01/envs/nidaba/lib/python2.7/site-packages/celery/app/trace.py", line 201, in on_error
    R = I.handle_error_state(task, eager=eager)
  File "/cluster/home/mmunso01/envs/nidaba/lib/python2.7/site-packages/celery/app/trace.py", line 85, in handle_error_state
    }[self.state](task, store_errors=store_errors)
  File "/cluster/home/mmunso01/envs/nidaba/lib/python2.7/site-packages/celery/app/trace.py", line 118, in handle_failure
    req.id, exc, einfo.traceback, request=req,
  File "/cluster/home/mmunso01/envs/nidaba/lib/python2.7/site-packages/celery/backends/base.py", line 121, in mark_as_failure
    traceback=traceback, request=request)
  File "/cluster/home/mmunso01/envs/nidaba/lib/python2.7/site-packages/celery/backends/base.py", line 256, in store_result
    request=request, **kwargs)
  File "/cluster/home/mmunso01/envs/nidaba/lib/python2.7/site-packages/celery/backends/base.py", line 490, in _store_result
    self.set(self.get_key_for_task(task_id), self.encode(meta))
  File "/cluster/home/mmunso01/envs/nidaba/lib/python2.7/site-packages/celery/backends/redis.py", line 160, in set
    return self.ensure(self._set, (key, value), **retry_policy)
  File "/cluster/home/mmunso01/envs/nidaba/lib/python2.7/site-packages/celery/backends/redis.py", line 149, in ensure
    **retry_policy
  File "/cluster/home/mmunso01/envs/nidaba/lib/python2.7/site-packages/kombu/utils/__init__.py", line 243, in retry_over_time
    return fun(*args, **kwargs)
  File "/cluster/home/mmunso01/envs/nidaba/lib/python2.7/site-packages/celery/backends/redis.py", line 169, in _set
    pipe.execute()
  File "/cluster/home/mmunso01/envs/nidaba/lib/python2.7/site-packages/redis/client.py", line 2578, in execute
    return execute(conn, stack, raise_on_error)
  File "/cluster/home/mmunso01/envs/nidaba/lib/python2.7/site-packages/redis/client.py", line 2475, in _execute_transaction
    raise errors[0][1]
ResponseError: Command # 1 (SETEX celery-task-meta-39d21efc-8966-40bb-b367-a6e871475d6b 86400 {"status": "FAILURE", "traceback": "Traceback (most recent call last):\n  File \"/cluster/home/mmunso01/envs/nidaba/lib/python2.7/site-packages/celery/app/trace.py\", line 240, in trace_task\n    R = retval = fun(*args, **kwargs)\n  File \"/cluster/home/mmunso01/envs/nidaba/lib/python2.7/site-packages/nidaba/tasks/helper.py\", line 89, in __call__\n    _redis_set_atomically(batch_id, task_id, 'errors', (nkwargs, e.message))\n  File \"/cluster/home/mmunso01/envs/nidaba/lib/python2.7/site-packages/nidaba/tasks/helper.py\", line 32, in _redis_set_atomically\n    pipe.execute()\n  File \"/cluster/home/mmunso01/envs/nidaba/lib/python2.7/site-packages/redis/client.py\", line 2578, in execute\n    return execute(conn, stack, raise_on_error)\n  File \"/cluster/home/mmunso01/envs/nidaba/lib/python2.7/site-packages/redis/client.py\", line 2473, in _execute_transaction\n    self.immediate_execute_command('DISCARD')\n  File \"/cluster/home/mmunso01/envs/nidaba/lib/python2.7/site-packages/redis/client.py\", line 2413, in immediate_execute_command\n    return self.parse_response(conn, command_name, **options)\n  File \"/cluster/home/mmunso01/envs/nidaba/lib/python2.7/site-packages/redis/client.py\", line 2536, in parse_response\n    self, connection, command_name, **options)\n  File \"/cluster/home/mmunso01/envs/nidaba/lib/python2.7/site-packages/redis/client.py\", line 577, in parse_response\n    response = connection.read_response()\n  File \"/cluster/home/mmunso01/envs/nidaba/lib/python2.7/site-packages/redis/connection.py\", line 574, in read_response\n    raise response\nResponseError: DISCARD without MULTI\n", "result": {"exc_message": "DISCARD without MULTI", "exc_type": "ResponseError"}, "children": []}) of pipeline caused error: MISCONF Redis is configured to save RDB snapshots, but is currently not able to persist on disk. Commands that may modify the data set are disabled. Please check Redis logs for details about the error.

  exc, exc_info.traceback)))
[2015-10-16 09:24:51,547: CRITICAL/MainProcess] Task nidaba.ocr.tesseract[a1674a8e-6461-46fa-a8d9-68664fb9fbf2] INTERNAL ERROR: ResponseError(u'Command # 1 (SETEX celery-task-meta-a1674a8e-6461-46fa-a8d9-68664fb9fbf2 86400 {"status": "FAILURE", "traceback": "Traceback (most recent call last):\\n  File \\"/cluster/home/mmunso01/envs/nidaba/lib/python2.7/site-packages/celery/app/trace.py\\", line 240, in trace_task\\n    R = retval = fun(*args, **kwargs)\\n  File \\"/cluster/home/mmunso01/envs/nidaba/lib/python2.7/site-packages/nidaba/tasks/helper.py\\", line 92, in __call__\\n    _redis_set_atomically(batch_id, task_id, \'state\', \'SUCCESS\')\\n  File \\"/cluster/home/mmunso01/envs/nidaba/lib/python2.7/site-packages/nidaba/tasks/helper.py\\", line 32, in _redis_set_atomically\\n    pipe.execute()\\n  File \\"/cluster/home/mmunso01/envs/nidaba/lib/python2.7/site-packages/redis/client.py\\", line 2578, in execute\\n    return execute(conn, stack, raise_on_error)\\n  File \\"/cluster/home/mmunso01/envs/nidaba/lib/python2.7/site-packages/redis/client.py\\", line 2473, in _execute_transaction\\n    self.immediate_execute_command(\'DISCARD\')\\n  File \\"/cluster/home/mmunso01/envs/nidaba/lib/python2.7/site-packages/redis/client.py\\", line 2413, in immediate_execute_command\\n    return self.parse_response(conn, command_name, **options)\\n  File \\"/cluster/home/mmunso01/envs/nidaba/lib/python2.7/site-packages/redis/client.py\\", line 2536, in parse_response\\n    self, connection, command_name, **options)\\n  File \\"/cluster/home/mmunso01/envs/nidaba/lib/python2.7/site-packages/redis/client.py\\", line 577, in parse_response\\n    response = connection.read_response()\\n  File \\"/cluster/home/mmunso01/envs/nidaba/lib/python2.7/site-packages/redis/connection.py\\", line 574, in read_response\\n    raise response\\nResponseError: DISCARD without MULTI\\n", "result": {"exc_message": "DISCARD without MULTI", "exc_type": "ResponseError"}, "children": []}) of pipeline caused error: MISCONF Redis is configured to save RDB snapshots, but is currently not able to persist on disk. Commands that may modify the data set are disabled. Please check Redis logs for details about the error.',)
Traceback (most recent call last):
  File "/cluster/home/mmunso01/envs/nidaba/lib/python2.7/site-packages/celery/app/trace.py", line 253, in trace_task
    I, R, state, retval = on_error(task_request, exc, uuid)
  File "/cluster/home/mmunso01/envs/nidaba/lib/python2.7/site-packages/celery/app/trace.py", line 201, in on_error
    R = I.handle_error_state(task, eager=eager)
  File "/cluster/home/mmunso01/envs/nidaba/lib/python2.7/site-packages/celery/app/trace.py", line 85, in handle_error_state
    }[self.state](task, store_errors=store_errors)
  File "/cluster/home/mmunso01/envs/nidaba/lib/python2.7/site-packages/celery/app/trace.py", line 118, in handle_failure
    req.id, exc, einfo.traceback, request=req,
  File "/cluster/home/mmunso01/envs/nidaba/lib/python2.7/site-packages/celery/backends/base.py", line 121, in mark_as_failure
    traceback=traceback, request=request)
  File "/cluster/home/mmunso01/envs/nidaba/lib/python2.7/site-packages/celery/backends/base.py", line 256, in store_result
    request=request, **kwargs)
  File "/cluster/home/mmunso01/envs/nidaba/lib/python2.7/site-packages/celery/backends/base.py", line 490, in _store_result
    self.set(self.get_key_for_task(task_id), self.encode(meta))
  File "/cluster/home/mmunso01/envs/nidaba/lib/python2.7/site-packages/celery/backends/redis.py", line 160, in set
    return self.ensure(self._set, (key, value), **retry_policy)
  File "/cluster/home/mmunso01/envs/nidaba/lib/python2.7/site-packages/celery/backends/redis.py", line 149, in ensure
    **retry_policy
  File "/cluster/home/mmunso01/envs/nidaba/lib/python2.7/site-packages/kombu/utils/__init__.py", line 243, in retry_over_time
    return fun(*args, **kwargs)
  File "/cluster/home/mmunso01/envs/nidaba/lib/python2.7/site-packages/celery/backends/redis.py", line 169, in _set
    pipe.execute()
  File "/cluster/home/mmunso01/envs/nidaba/lib/python2.7/site-packages/redis/client.py", line 2578, in execute
    return execute(conn, stack, raise_on_error)
  File "/cluster/home/mmunso01/envs/nidaba/lib/python2.7/site-packages/redis/client.py", line 2475, in _execute_transaction
    raise errors[0][1]
ResponseError: Command # 1 (SETEX celery-task-meta-a1674a8e-6461-46fa-a8d9-68664fb9fbf2 86400 {"status": "FAILURE", "traceback": "Traceback (most recent call last):\n  File \"/cluster/home/mmunso01/envs/nidaba/lib/python2.7/site-packages/celery/app/trace.py\", line 240, in trace_task\n    R = retval = fun(*args, **kwargs)\n  File \"/cluster/home/mmunso01/envs/nidaba/lib/python2.7/site-packages/nidaba/tasks/helper.py\", line 92, in __call__\n    _redis_set_atomically(batch_id, task_id, 'state', 'SUCCESS')\n  File \"/cluster/home/mmunso01/envs/nidaba/lib/python2.7/site-packages/nidaba/tasks/helper.py\", line 32, in _redis_set_atomically\n    pipe.execute()\n  File \"/cluster/home/mmunso01/envs/nidaba/lib/python2.7/site-packages/redis/client.py\", line 2578, in execute\n    return execute(conn, stack, raise_on_error)\n  File \"/cluster/home/mmunso01/envs/nidaba/lib/python2.7/site-packages/redis/client.py\", line 2473, in _execute_transaction\n    self.immediate_execute_command('DISCARD')\n  File \"/cluster/home/mmunso01/envs/nidaba/lib/python2.7/site-packages/redis/client.py\", line 2413, in immediate_execute_command\n    return self.parse_response(conn, command_name, **options)\n  File \"/cluster/home/mmunso01/envs/nidaba/lib/python2.7/site-packages/redis/client.py\", line 2536, in parse_response\n    self, connection, command_name, **options)\n  File \"/cluster/home/mmunso01/envs/nidaba/lib/python2.7/site-packages/redis/client.py\", line 577, in parse_response\n    response = connection.read_response()\n  File \"/cluster/home/mmunso01/envs/nidaba/lib/python2.7/site-packages/redis/connection.py\", line 574, in read_response\n    raise response\nResponseError: DISCARD without MULTI\n", "result": {"exc_message": "DISCARD without MULTI", "exc_type": "ResponseError"}, "children": []}) of pipeline caused error: MISCONF Redis is configured to save RDB snapshots, but is currently not able to persist on disk. Commands that may modify the data set are disabled. Please check Redis logs for details about the error.
[2015-10-16 09:24:52,051: CRITICAL/MainProcess] Task nidaba.postprocessing.spell_check[39d21efc-8966-40bb-b367-a6e871475d6b] INTERNAL ERROR: ResponseError(u'Command # 1 (SETEX celery-task-meta-39d21efc-8966-40bb-b367-a6e871475d6b 86400 {"status": "FAILURE", "traceback": "Traceback (most recent call last):\\n  File \\"/cluster/home/mmunso01/envs/nidaba/lib/python2.7/site-packages/celery/app/trace.py\\", line 240, in trace_task\\n    R = retval = fun(*args, **kwargs)\\n  File \\"/cluster/home/mmunso01/envs/nidaba/lib/python2.7/site-packages/nidaba/tasks/helper.py\\", line 89, in __call__\\n    _redis_set_atomically(batch_id, task_id, \'errors\', (nkwargs, e.message))\\n  File \\"/cluster/home/mmunso01/envs/nidaba/lib/python2.7/site-packages/nidaba/tasks/helper.py\\", line 32, in _redis_set_atomically\\n    pipe.execute()\\n  File \\"/cluster/home/mmunso01/envs/nidaba/lib/python2.7/site-packages/redis/client.py\\", line 2578, in execute\\n    return execute(conn, stack, raise_on_error)\\n  File \\"/cluster/home/mmunso01/envs/nidaba/lib/python2.7/site-packages/redis/client.py\\", line 2473, in _execute_transaction\\n    self.immediate_execute_command(\'DISCARD\')\\n  File \\"/cluster/home/mmunso01/envs/nidaba/lib/python2.7/site-packages/redis/client.py\\", line 2413, in immediate_execute_command\\n    return self.parse_response(conn, command_name, **options)\\n  File \\"/cluster/home/mmunso01/envs/nidaba/lib/python2.7/site-packages/redis/client.py\\", line 2536, in parse_response\\n    self, connection, command_name, **options)\\n  File \\"/cluster/home/mmunso01/envs/nidaba/lib/python2.7/site-packages/redis/client.py\\", line 577, in parse_response\\n    response = connection.read_response()\\n  File \\"/cluster/home/mmunso01/envs/nidaba/lib/python2.7/site-packages/redis/connection.py\\", line 574, in read_response\\n    raise response\\nResponseError: DISCARD without MULTI\\n", "result": {"exc_message": "DISCARD without MULTI", "exc_type": "ResponseError"}, "children": []}) of pipeline caused error: MISCONF Redis is configured to save RDB snapshots, but is currently not able to persist on disk. Commands that may modify the data set are disabled. Please check Redis logs for details about the error.',)
Traceback (most recent call last):
  File "/cluster/home/mmunso01/envs/nidaba/lib/python2.7/site-packages/celery/app/trace.py", line 253, in trace_task
    I, R, state, retval = on_error(task_request, exc, uuid)
  File "/cluster/home/mmunso01/envs/nidaba/lib/python2.7/site-packages/celery/app/trace.py", line 201, in on_error
    R = I.handle_error_state(task, eager=eager)
  File "/cluster/home/mmunso01/envs/nidaba/lib/python2.7/site-packages/celery/app/trace.py", line 85, in handle_error_state
    }[self.state](task, store_errors=store_errors)
  File "/cluster/home/mmunso01/envs/nidaba/lib/python2.7/site-packages/celery/app/trace.py", line 118, in handle_failure
    req.id, exc, einfo.traceback, request=req,
  File "/cluster/home/mmunso01/envs/nidaba/lib/python2.7/site-packages/celery/backends/base.py", line 121, in mark_as_failure
    traceback=traceback, request=request)
  File "/cluster/home/mmunso01/envs/nidaba/lib/python2.7/site-packages/celery/backends/base.py", line 256, in store_result
    request=request, **kwargs)
  File "/cluster/home/mmunso01/envs/nidaba/lib/python2.7/site-packages/celery/backends/base.py", line 490, in _store_result
    self.set(self.get_key_for_task(task_id), self.encode(meta))
  File "/cluster/home/mmunso01/envs/nidaba/lib/python2.7/site-packages/celery/backends/redis.py", line 160, in set
    return self.ensure(self._set, (key, value), **retry_policy)
  File "/cluster/home/mmunso01/envs/nidaba/lib/python2.7/site-packages/celery/backends/redis.py", line 149, in ensure
    **retry_policy
  File "/cluster/home/mmunso01/envs/nidaba/lib/python2.7/site-packages/kombu/utils/__init__.py", line 243, in retry_over_time
    return fun(*args, **kwargs)
  File "/cluster/home/mmunso01/envs/nidaba/lib/python2.7/site-packages/celery/backends/redis.py", line 169, in _set
    pipe.execute()
  File "/cluster/home/mmunso01/envs/nidaba/lib/python2.7/site-packages/redis/client.py", line 2578, in execute
    return execute(conn, stack, raise_on_error)
  File "/cluster/home/mmunso01/envs/nidaba/lib/python2.7/site-packages/redis/client.py", line 2475, in _execute_transaction
    raise errors[0][1]
ResponseError: Command # 1 (SETEX celery-task-meta-39d21efc-8966-40bb-b367-a6e871475d6b 86400 {"status": "FAILURE", "traceback": "Traceback (most recent call last):\n  File \"/cluster/home/mmunso01/envs/nidaba/lib/python2.7/site-packages/celery/app/trace.py\", line 240, in trace_task\n    R = retval = fun(*args, **kwargs)\n  File \"/cluster/home/mmunso01/envs/nidaba/lib/python2.7/site-packages/nidaba/tasks/helper.py\", line 89, in __call__\n    _redis_set_atomically(batch_id, task_id, 'errors', (nkwargs, e.message))\n  File \"/cluster/home/mmunso01/envs/nidaba/lib/python2.7/site-packages/nidaba/tasks/helper.py\", line 32, in _redis_set_atomically\n    pipe.execute()\n  File \"/cluster/home/mmunso01/envs/nidaba/lib/python2.7/site-packages/redis/client.py\", line 2578, in execute\n    return execute(conn, stack, raise_on_error)\n  File \"/cluster/home/mmunso01/envs/nidaba/lib/python2.7/site-packages/redis/client.py\", line 2473, in _execute_transaction\n    self.immediate_execute_command('DISCARD')\n  File \"/cluster/home/mmunso01/envs/nidaba/lib/python2.7/site-packages/redis/client.py\", line 2413, in immediate_execute_command\n    return self.parse_response(conn, command_name, **options)\n  File \"/cluster/home/mmunso01/envs/nidaba/lib/python2.7/site-packages/redis/client.py\", line 2536, in parse_response\n    self, connection, command_name, **options)\n  File \"/cluster/home/mmunso01/envs/nidaba/lib/python2.7/site-packages/redis/client.py\", line 577, in parse_response\n    response = connection.read_response()\n  File \"/cluster/home/mmunso01/envs/nidaba/lib/python2.7/site-packages/redis/connection.py\", line 574, in read_response\n    raise response\nResponseError: DISCARD without MULTI\n", "result": {"exc_message": "DISCARD without MULTI", "exc_type": "ResponseError"}, "children": []}) of pipeline caused error: MISCONF Redis is configured to save RDB snapshots, but is currently not able to persist on disk. Commands that may modify the data set are disabled. Please check Redis logs for details about the error.
[2015-10-16 09:24:52,532: WARNING/Worker-30] /cluster/home/mmunso01/envs/nidaba/lib/python2.7/site-packages/celery/app/trace.py:365: RuntimeWarning: Exception raised outside body: ResponseError(u'Command # 1 (SETEX celery-task-meta-a55b745f-151a-4e1b-9392-e8a9694ba2ec 86400 {"status": "FAILURE", "traceback": "Traceback (most recent call last):\\n  File \\"/cluster/home/mmunso01/envs/nidaba/lib/python2.7/site-packages/celery/app/trace.py\\", line 240, in trace_task\\n    R = retval = fun(*args, **kwargs)\\n  File \\"/cluster/home/mmunso01/envs/nidaba/lib/python2.7/site-packages/nidaba/tasks/helper.py\\", line 92, in __call__\\n    _redis_set_atomically(batch_id, task_id, \'state\', \'SUCCESS\')\\n  File \\"/cluster/home/mmunso01/envs/nidaba/lib/python2.7/site-packages/nidaba/tasks/helper.py\\", line 32, in _redis_set_atomically\\n    pipe.execute()\\n  File \\"/cluster/home/mmunso01/envs/nidaba/lib/python2.7/site-packages/redis/client.py\\", line 2578, in execute\\n    return execute(conn, stack, raise_on_error)\\n  File \\"/cluster/home/mmunso01/envs/nidaba/lib/python2.7/site-packages/redis/client.py\\", line 2473, in _execute_transaction\\n    self.immediate_execute_command(\'DISCARD\')\\n  File \\"/cluster/home/mmunso01/envs/nidaba/lib/python2.7/site-packages/redis/client.py\\", line 2413, in immediate_execute_command\\n    return self.parse_response(conn, command_name, **options)\\n  File \\"/cluster/home/mmunso01/envs/nidaba/lib/python2.7/site-packages/redis/client.py\\", line 2536, in parse_response\\n    self, connection, command_name, **options)\\n  File \\"/cluster/home/mmunso01/envs/nidaba/lib/python2.7/site-packages/redis/client.py\\", line 577, in parse_response\\n    response = connection.read_response()\\n  File \\"/cluster/home/mmunso01/envs/nidaba/lib/python2.7/site-packages/redis/connection.py\\", line 574, in read_response\\n    raise response\\nResponseError: DISCARD without MULTI\\n", "result": {"exc_message": "DISCARD without MULTI", "exc_type": "ResponseError"}, "children": []}) of pipeline caused error: MISCONF Redis is configured to save RDB snapshots, but is currently not able to persist on disk. Commands that may modify the data set are disabled. Please check Redis logs for details about the error.',):
Traceback (most recent call last):
  File "/cluster/home/mmunso01/envs/nidaba/lib/python2.7/site-packages/celery/app/trace.py", line 253, in trace_task
    I, R, state, retval = on_error(task_request, exc, uuid)
  File "/cluster/home/mmunso01/envs/nidaba/lib/python2.7/site-packages/celery/app/trace.py", line 201, in on_error
    R = I.handle_error_state(task, eager=eager)
  File "/cluster/home/mmunso01/envs/nidaba/lib/python2.7/site-packages/celery/app/trace.py", line 85, in handle_error_state
    }[self.state](task, store_errors=store_errors)
  File "/cluster/home/mmunso01/envs/nidaba/lib/python2.7/site-packages/celery/app/trace.py", line 118, in handle_failure
    req.id, exc, einfo.traceback, request=req,
  File "/cluster/home/mmunso01/envs/nidaba/lib/python2.7/site-packages/celery/backends/base.py", line 121, in mark_as_failure
    traceback=traceback, request=request)
  File "/cluster/home/mmunso01/envs/nidaba/lib/python2.7/site-packages/celery/backends/base.py", line 256, in store_result
    request=request, **kwargs)
  File "/cluster/home/mmunso01/envs/nidaba/lib/python2.7/site-packages/celery/backends/base.py", line 490, in _store_result
    self.set(self.get_key_for_task(task_id), self.encode(meta))
  File "/cluster/home/mmunso01/envs/nidaba/lib/python2.7/site-packages/celery/backends/redis.py", line 160, in set
    return self.ensure(self._set, (key, value), **retry_policy)
  File "/cluster/home/mmunso01/envs/nidaba/lib/python2.7/site-packages/celery/backends/redis.py", line 149, in ensure
    **retry_policy
  File "/cluster/home/mmunso01/envs/nidaba/lib/python2.7/site-packages/kombu/utils/__init__.py", line 243, in retry_over_time
    return fun(*args, **kwargs)
  File "/cluster/home/mmunso01/envs/nidaba/lib/python2.7/site-packages/celery/backends/redis.py", line 169, in _set
    pipe.execute()
  File "/cluster/home/mmunso01/envs/nidaba/lib/python2.7/site-packages/redis/client.py", line 2578, in execute
    return execute(conn, stack, raise_on_error)
  File "/cluster/home/mmunso01/envs/nidaba/lib/python2.7/site-packages/redis/client.py", line 2475, in _execute_transaction
    raise errors[0][1]
ResponseError: Command # 1 (SETEX celery-task-meta-a55b745f-151a-4e1b-9392-e8a9694ba2ec 86400 {"status": "FAILURE", "traceback": "Traceback (most recent call last):\n  File \"/cluster/home/mmunso01/envs/nidaba/lib/python2.7/site-packages/celery/app/trace.py\", line 240, in trace_task\n    R = retval = fun(*args, **kwargs)\n  File \"/cluster/home/mmunso01/envs/nidaba/lib/python2.7/site-packages/nidaba/tasks/helper.py\", line 92, in __call__\n    _redis_set_atomically(batch_id, task_id, 'state', 'SUCCESS')\n  File \"/cluster/home/mmunso01/envs/nidaba/lib/python2.7/site-packages/nidaba/tasks/helper.py\", line 32, in _redis_set_atomically\n    pipe.execute()\n  File \"/cluster/home/mmunso01/envs/nidaba/lib/python2.7/site-packages/redis/client.py\", line 2578, in execute\n    return execute(conn, stack, raise_on_error)\n  File \"/cluster/home/mmunso01/envs/nidaba/lib/python2.7/site-packages/redis/client.py\", line 2473, in _execute_transaction\n    self.immediate_execute_command('DISCARD')\n  File \"/cluster/home/mmunso01/envs/nidaba/lib/python2.7/site-packages/redis/client.py\", line 2413, in immediate_execute_command\n    return self.parse_response(conn, command_name, **options)\n  File \"/cluster/home/mmunso01/envs/nidaba/lib/python2.7/site-packages/redis/client.py\", line 2536, in parse_response\n    self, connection, command_name, **options)\n  File \"/cluster/home/mmunso01/envs/nidaba/lib/python2.7/site-packages/redis/client.py\", line 577, in parse_response\n    response = connection.read_response()\n  File \"/cluster/home/mmunso01/envs/nidaba/lib/python2.7/site-packages/redis/connection.py\", line 574, in read_response\n    raise response\nResponseError: DISCARD without MULTI\n", "result": {"exc_message": "DISCARD without MULTI", "exc_type": "ResponseError"}, "children": []}) of pipeline caused error: MISCONF Redis is configured to save RDB snapshots, but is currently not able to persist on disk. Commands that may modify the data set are disabled. Please check Redis logs for details about the error.

  exc, exc_info.traceback)))
[2015-10-16 09:24:52,547: WARNING/Worker-30] /cluster/home/mmunso01/envs/nidaba/lib/python2.7/site-packages/celery/app/trace.py:365: RuntimeWarning: Exception raised outside body: ResponseError(u'Command # 1 (SETEX celery-task-meta-b47ae283-4898-4830-9637-c284fa38fff6 86400 {"status": "FAILURE", "traceback": "Traceback (most recent call last):\\n  File \\"/cluster/home/mmunso01/envs/nidaba/lib/python2.7/site-packages/celery/app/trace.py\\", line 240, in trace_task\\n    R = retval = fun(*args, **kwargs)\\n  File \\"/cluster/home/mmunso01/envs/nidaba/lib/python2.7/site-packages/nidaba/tasks/helper.py\\", line 89, in __call__\\n    _redis_set_atomically(batch_id, task_id, \'errors\', (nkwargs, e.message))\\n  File \\"/cluster/home/mmunso01/envs/nidaba/lib/python2.7/site-packages/nidaba/tasks/helper.py\\", line 32, in _redis_set_atomically\\n    pipe.execute()\\n  File \\"/cluster/home/mmunso01/envs/nidaba/lib/python2.7/site-packages/redis/client.py\\", line 2578, in execute\\n    return execute(conn, stack, raise_on_error)\\n  File \\"/cluster/home/mmunso01/envs/nidaba/lib/python2.7/site-packages/redis/client.py\\", line 2473, in _execute_transaction\\n    self.immediate_execute_command(\'DISCARD\')\\n  File \\"/cluster/home/mmunso01/envs/nidaba/lib/python2.7/site-packages/redis/client.py\\", line 2413, in immediate_execute_command\\n    return self.parse_response(conn, command_name, **options)\\n  File \\"/cluster/home/mmunso01/envs/nidaba/lib/python2.7/site-packages/redis/client.py\\", line 2536, in parse_response\\n    self, connection, command_name, **options)\\n  File \\"/cluster/home/mmunso01/envs/nidaba/lib/python2.7/site-packages/redis/client.py\\", line 577, in parse_response\\n    response = connection.read_response()\\n  File \\"/cluster/home/mmunso01/envs/nidaba/lib/python2.7/site-packages/redis/connection.py\\", line 574, in read_response\\n    raise response\\nResponseError: DISCARD without MULTI\\n", "result": {"exc_message": "DISCARD without MULTI", "exc_type": "ResponseError"}, "children": []}) of pipeline caused error: MISCONF Redis is configured to save RDB snapshots, but is currently not able to persist on disk. Commands that may modify the data set are disabled. Please check Redis logs for details about the error.',):
Traceback (most recent call last):
  File "/cluster/home/mmunso01/envs/nidaba/lib/python2.7/site-packages/celery/app/trace.py", line 253, in trace_task
    I, R, state, retval = on_error(task_request, exc, uuid)
  File "/cluster/home/mmunso01/envs/nidaba/lib/python2.7/site-packages/celery/app/trace.py", line 201, in on_error
    R = I.handle_error_state(task, eager=eager)
  File "/cluster/home/mmunso01/envs/nidaba/lib/python2.7/site-packages/celery/app/trace.py", line 85, in handle_error_state
    }[self.state](task, store_errors=store_errors)
  File "/cluster/home/mmunso01/envs/nidaba/lib/python2.7/site-packages/celery/app/trace.py", line 118, in handle_failure
    req.id, exc, einfo.traceback, request=req,
  File "/cluster/home/mmunso01/envs/nidaba/lib/python2.7/site-packages/celery/backends/base.py", line 121, in mark_as_failure
    traceback=traceback, request=request)
  File "/cluster/home/mmunso01/envs/nidaba/lib/python2.7/site-packages/celery/backends/base.py", line 256, in store_result
    request=request, **kwargs)
  File "/cluster/home/mmunso01/envs/nidaba/lib/python2.7/site-packages/celery/backends/base.py", line 490, in _store_result
    self.set(self.get_key_for_task(task_id), self.encode(meta))
  File "/cluster/home/mmunso01/envs/nidaba/lib/python2.7/site-packages/celery/backends/redis.py", line 160, in set
    return self.ensure(self._set, (key, value), **retry_policy)
  File "/cluster/home/mmunso01/envs/nidaba/lib/python2.7/site-packages/celery/backends/redis.py", line 149, in ensure
    **retry_policy
  File "/cluster/home/mmunso01/envs/nidaba/lib/python2.7/site-packages/kombu/utils/__init__.py", line 243, in retry_over_time
    return fun(*args, **kwargs)
  File "/cluster/home/mmunso01/envs/nidaba/lib/python2.7/site-packages/celery/backends/redis.py", line 169, in _set
    pipe.execute()
  File "/cluster/home/mmunso01/envs/nidaba/lib/python2.7/site-packages/redis/client.py", line 2578, in execute
    return execute(conn, stack, raise_on_error)
  File "/cluster/home/mmunso01/envs/nidaba/lib/python2.7/site-packages/redis/client.py", line 2475, in _execute_transaction
    raise errors[0][1]
ResponseError: Command # 1 (SETEX celery-task-meta-b47ae283-4898-4830-9637-c284fa38fff6 86400 {"status": "FAILURE", "traceback": "Traceback (most recent call last):\n  File \"/cluster/home/mmunso01/envs/nidaba/lib/python2.7/site-packages/celery/app/trace.py\", line 240, in trace_task\n    R = retval = fun(*args, **kwargs)\n  File \"/cluster/home/mmunso01/envs/nidaba/lib/python2.7/site-packages/nidaba/tasks/helper.py\", line 89, in __call__\n    _redis_set_atomically(batch_id, task_id, 'errors', (nkwargs, e.message))\n  File \"/cluster/home/mmunso01/envs/nidaba/lib/python2.7/site-packages/nidaba/tasks/helper.py\", line 32, in _redis_set_atomically\n    pipe.execute()\n  File \"/cluster/home/mmunso01/envs/nidaba/lib/python2.7/site-packages/redis/client.py\", line 2578, in execute\n    return execute(conn, stack, raise_on_error)\n  File \"/cluster/home/mmunso01/envs/nidaba/lib/python2.7/site-packages/redis/client.py\", line 2473, in _execute_transaction\n    self.immediate_execute_command('DISCARD')\n  File \"/cluster/home/mmunso01/envs/nidaba/lib/python2.7/site-packages/redis/client.py\", line 2413, in immediate_execute_command\n    return self.parse_response(conn, command_name, **options)\n  File \"/cluster/home/mmunso01/envs/nidaba/lib/python2.7/site-packages/redis/client.py\", line 2536, in parse_response\n    self, connection, command_name, **options)\n  File \"/cluster/home/mmunso01/envs/nidaba/lib/python2.7/site-packages/redis/client.py\", line 577, in parse_response\n    response = connection.read_response()\n  File \"/cluster/home/mmunso01/envs/nidaba/lib/python2.7/site-packages/redis/connection.py\", line 574, in read_response\n    raise response\nResponseError: DISCARD without MULTI\n", "result": {"exc_message": "DISCARD without MULTI", "exc_type": "ResponseError"}, "children": []}) of pipeline caused error: MISCONF Redis is configured to save RDB snapshots, but is currently not able to persist on disk. Commands that may modify the data set are disabled. Please check Redis logs for details about the error.

  exc, exc_info.traceback)))
[2015-10-16 09:24:52,574: CRITICAL/MainProcess] Task nidaba.ocr.tesseract[a55b745f-151a-4e1b-9392-e8a9694ba2ec] INTERNAL ERROR: ResponseError(u'Command # 1 (SETEX celery-task-meta-a55b745f-151a-4e1b-9392-e8a9694ba2ec 86400 {"status": "FAILURE", "traceback": "Traceback (most recent call last):\\n  File \\"/cluster/home/mmunso01/envs/nidaba/lib/python2.7/site-packages/celery/app/trace.py\\", line 240, in trace_task\\n    R = retval = fun(*args, **kwargs)\\n  File \\"/cluster/home/mmunso01/envs/nidaba/lib/python2.7/site-packages/nidaba/tasks/helper.py\\", line 92, in __call__\\n    _redis_set_atomically(batch_id, task_id, \'state\', \'SUCCESS\')\\n  File \\"/cluster/home/mmunso01/envs/nidaba/lib/python2.7/site-packages/nidaba/tasks/helper.py\\", line 32, in _redis_set_atomically\\n    pipe.execute()\\n  File \\"/cluster/home/mmunso01/envs/nidaba/lib/python2.7/site-packages/redis/client.py\\", line 2578, in execute\\n    return execute(conn, stack, raise_on_error)\\n  File \\"/cluster/home/mmunso01/envs/nidaba/lib/python2.7/site-packages/redis/client.py\\", line 2473, in _execute_transaction\\n    self.immediate_execute_command(\'DISCARD\')\\n  File \\"/cluster/home/mmunso01/envs/nidaba/lib/python2.7/site-packages/redis/client.py\\", line 2413, in immediate_execute_command\\n    return self.parse_response(conn, command_name, **options)\\n  File \\"/cluster/home/mmunso01/envs/nidaba/lib/python2.7/site-packages/redis/client.py\\", line 2536, in parse_response\\n    self, connection, command_name, **options)\\n  File \\"/cluster/home/mmunso01/envs/nidaba/lib/python2.7/site-packages/redis/client.py\\", line 577, in parse_response\\n    response = connection.read_response()\\n  File \\"/cluster/home/mmunso01/envs/nidaba/lib/python2.7/site-packages/redis/connection.py\\", line 574, in read_response\\n    raise response\\nResponseError: DISCARD without MULTI\\n", "result": {"exc_message": "DISCARD without MULTI", "exc_type": "ResponseError"}, "children": []}) of pipeline caused error: MISCONF Redis is configured to save RDB snapshots, but is currently not able to persist on disk. Commands that may modify the data set are disabled. Please check Redis logs for details about the error.',)
Traceback (most recent call last):
  File "/cluster/home/mmunso01/envs/nidaba/lib/python2.7/site-packages/celery/app/trace.py", line 253, in trace_task
    I, R, state, retval = on_error(task_request, exc, uuid)
  File "/cluster/home/mmunso01/envs/nidaba/lib/python2.7/site-packages/celery/app/trace.py", line 201, in on_error
    R = I.handle_error_state(task, eager=eager)
  File "/cluster/home/mmunso01/envs/nidaba/lib/python2.7/site-packages/celery/app/trace.py", line 85, in handle_error_state
    }[self.state](task, store_errors=store_errors)
  File "/cluster/home/mmunso01/envs/nidaba/lib/python2.7/site-packages/celery/app/trace.py", line 118, in handle_failure
    req.id, exc, einfo.traceback, request=req,
  File "/cluster/home/mmunso01/envs/nidaba/lib/python2.7/site-packages/celery/backends/base.py", line 121, in mark_as_failure
    traceback=traceback, request=request)
  File "/cluster/home/mmunso01/envs/nidaba/lib/python2.7/site-packages/celery/backends/base.py", line 256, in store_result
    request=request, **kwargs)
  File "/cluster/home/mmunso01/envs/nidaba/lib/python2.7/site-packages/celery/backends/base.py", line 490, in _store_result
    self.set(self.get_key_for_task(task_id), self.encode(meta))
  File "/cluster/home/mmunso01/envs/nidaba/lib/python2.7/site-packages/celery/backends/redis.py", line 160, in set
    return self.ensure(self._set, (key, value), **retry_policy)
  File "/cluster/home/mmunso01/envs/nidaba/lib/python2.7/site-packages/celery/backends/redis.py", line 149, in ensure
    **retry_policy
  File "/cluster/home/mmunso01/envs/nidaba/lib/python2.7/site-packages/kombu/utils/__init__.py", line 243, in retry_over_time
    return fun(*args, **kwargs)
  File "/cluster/home/mmunso01/envs/nidaba/lib/python2.7/site-packages/celery/backends/redis.py", line 169, in _set
    pipe.execute()
  File "/cluster/home/mmunso01/envs/nidaba/lib/python2.7/site-packages/redis/client.py", line 2578, in execute
    return execute(conn, stack, raise_on_error)
  File "/cluster/home/mmunso01/envs/nidaba/lib/python2.7/site-packages/redis/client.py", line 2475, in _execute_transaction
    raise errors[0][1]
ResponseError: Command # 1 (SETEX celery-task-meta-a55b745f-151a-4e1b-9392-e8a9694ba2ec 86400 {"status": "FAILURE", "traceback": "Traceback (most recent call last):\n  File \"/cluster/home/mmunso01/envs/nidaba/lib/python2.7/site-packages/celery/app/trace.py\", line 240, in trace_task\n    R = retval = fun(*args, **kwargs)\n  File \"/cluster/home/mmunso01/envs/nidaba/lib/python2.7/site-packages/nidaba/tasks/helper.py\", line 92, in __call__\n    _redis_set_atomically(batch_id, task_id, 'state', 'SUCCESS')\n  File \"/cluster/home/mmunso01/envs/nidaba/lib/python2.7/site-packages/nidaba/tasks/helper.py\", line 32, in _redis_set_atomically\n    pipe.execute()\n  File \"/cluster/home/mmunso01/envs/nidaba/lib/python2.7/site-packages/redis/client.py\", line 2578, in execute\n    return execute(conn, stack, raise_on_error)\n  File \"/cluster/home/mmunso01/envs/nidaba/lib/python2.7/site-packages/redis/client.py\", line 2473, in _execute_transaction\n    self.immediate_execute_command('DISCARD')\n  File \"/cluster/home/mmunso01/envs/nidaba/lib/python2.7/site-packages/redis/client.py\", line 2413, in immediate_execute_command\n    return self.parse_response(conn, command_name, **options)\n  File \"/cluster/home/mmunso01/envs/nidaba/lib/python2.7/site-packages/redis/client.py\", line 2536, in parse_response\n    self, connection, command_name, **options)\n  File \"/cluster/home/mmunso01/envs/nidaba/lib/python2.7/site-packages/redis/client.py\", line 577, in parse_response\n    response = connection.read_response()\n  File \"/cluster/home/mmunso01/envs/nidaba/lib/python2.7/site-packages/redis/connection.py\", line 574, in read_response\n    raise response\nResponseError: DISCARD without MULTI\n", "result": {"exc_message": "DISCARD without MULTI", "exc_type": "ResponseError"}, "children": []}) of pipeline caused error: MISCONF Redis is configured to save RDB snapshots, but is currently not able to persist on disk. Commands that may modify the data set are disabled. Please check Redis logs for details about the error.
[2015-10-16 09:24:52,576: CRITICAL/MainProcess] Task nidaba.postprocessing.spell_check[b47ae283-4898-4830-9637-c284fa38fff6] INTERNAL ERROR: ResponseError(u'Command # 1 (SETEX celery-task-meta-b47ae283-4898-4830-9637-c284fa38fff6 86400 {"status": "FAILURE", "traceback": "Traceback (most recent call last):\\n  File \\"/cluster/home/mmunso01/envs/nidaba/lib/python2.7/site-packages/celery/app/trace.py\\", line 240, in trace_task\\n    R = retval = fun(*args, **kwargs)\\n  File \\"/cluster/home/mmunso01/envs/nidaba/lib/python2.7/site-packages/nidaba/tasks/helper.py\\", line 89, in __call__\\n    _redis_set_atomically(batch_id, task_id, \'errors\', (nkwargs, e.message))\\n  File \\"/cluster/home/mmunso01/envs/nidaba/lib/python2.7/site-packages/nidaba/tasks/helper.py\\", line 32, in _redis_set_atomically\\n    pipe.execute()\\n  File \\"/cluster/home/mmunso01/envs/nidaba/lib/python2.7/site-packages/redis/client.py\\", line 2578, in execute\\n    return execute(conn, stack, raise_on_error)\\n  File \\"/cluster/home/mmunso01/envs/nidaba/lib/python2.7/site-packages/redis/client.py\\", line 2473, in _execute_transaction\\n    self.immediate_execute_command(\'DISCARD\')\\n  File \\"/cluster/home/mmunso01/envs/nidaba/lib/python2.7/site-packages/redis/client.py\\", line 2413, in immediate_execute_command\\n    return self.parse_response(conn, command_name, **options)\\n  File \\"/cluster/home/mmunso01/envs/nidaba/lib/python2.7/site-packages/redis/client.py\\", line 2536, in parse_response\\n    self, connection, command_name, **options)\\n  File \\"/cluster/home/mmunso01/envs/nidaba/lib/python2.7/site-packages/redis/client.py\\", line 577, in parse_response\\n    response = connection.read_response()\\n  File \\"/cluster/home/mmunso01/envs/nidaba/lib/python2.7/site-packages/redis/connection.py\\", line 574, in read_response\\n    raise response\\nResponseError: DISCARD without MULTI\\n", "result": {"exc_message": "DISCARD without MULTI", "exc_type": "ResponseError"}, "children": []}) of pipeline caused error: MISCONF Redis is configured to save RDB snapshots, but is currently not able to persist on disk. Commands that may modify the data set are disabled. Please check Redis logs for details about the error.',)
Traceback (most recent call last):
  File "/cluster/home/mmunso01/envs/nidaba/lib/python2.7/site-packages/celery/app/trace.py", line 253, in trace_task
    I, R, state, retval = on_error(task_request, exc, uuid)
  File "/cluster/home/mmunso01/envs/nidaba/lib/python2.7/site-packages/celery/app/trace.py", line 201, in on_error
    R = I.handle_error_state(task, eager=eager)
  File "/cluster/home/mmunso01/envs/nidaba/lib/python2.7/site-packages/celery/app/trace.py", line 85, in handle_error_state
    }[self.state](task, store_errors=store_errors)
  File "/cluster/home/mmunso01/envs/nidaba/lib/python2.7/site-packages/celery/app/trace.py", line 118, in handle_failure
    req.id, exc, einfo.traceback, request=req,
  File "/cluster/home/mmunso01/envs/nidaba/lib/python2.7/site-packages/celery/backends/base.py", line 121, in mark_as_failure
    traceback=traceback, request=request)
  File "/cluster/home/mmunso01/envs/nidaba/lib/python2.7/site-packages/celery/backends/base.py", line 256, in store_result
    request=request, **kwargs)
  File "/cluster/home/mmunso01/envs/nidaba/lib/python2.7/site-packages/celery/backends/base.py", line 490, in _store_result
    self.set(self.get_key_for_task(task_id), self.encode(meta))
  File "/cluster/home/mmunso01/envs/nidaba/lib/python2.7/site-packages/celery/backends/redis.py", line 160, in set
    return self.ensure(self._set, (key, value), **retry_policy)
  File "/cluster/home/mmunso01/envs/nidaba/lib/python2.7/site-packages/celery/backends/redis.py", line 149, in ensure
    **retry_policy
  File "/cluster/home/mmunso01/envs/nidaba/lib/python2.7/site-packages/kombu/utils/__init__.py", line 243, in retry_over_time
    return fun(*args, **kwargs)
  File "/cluster/home/mmunso01/envs/nidaba/lib/python2.7/site-packages/celery/backends/redis.py", line 169, in _set
    pipe.execute()
  File "/cluster/home/mmunso01/envs/nidaba/lib/python2.7/site-packages/redis/client.py", line 2578, in execute
    return execute(conn, stack, raise_on_error)
  File "/cluster/home/mmunso01/envs/nidaba/lib/python2.7/site-packages/redis/client.py", line 2475, in _execute_transaction
    raise errors[0][1]
ResponseError: Command # 1 (SETEX celery-task-meta-b47ae283-4898-4830-9637-c284fa38fff6 86400 {"status": "FAILURE", "traceback": "Traceback (most recent call last):\n  File \"/cluster/home/mmunso01/envs/nidaba/lib/python2.7/site-packages/celery/app/trace.py\", line 240, in trace_task\n    R = retval = fun(*args, **kwargs)\n  File \"/cluster/home/mmunso01/envs/nidaba/lib/python2.7/site-packages/nidaba/tasks/helper.py\", line 89, in __call__\n    _redis_set_atomically(batch_id, task_id, 'errors', (nkwargs, e.message))\n  File \"/cluster/home/mmunso01/envs/nidaba/lib/python2.7/site-packages/nidaba/tasks/helper.py\", line 32, in _redis_set_atomically\n    pipe.execute()\n  File \"/cluster/home/mmunso01/envs/nidaba/lib/python2.7/site-packages/redis/client.py\", line 2578, in execute\n    return execute(conn, stack, raise_on_error)\n  File \"/cluster/home/mmunso01/envs/nidaba/lib/python2.7/site-packages/redis/client.py\", line 2473, in _execute_transaction\n    self.immediate_execute_command('DISCARD')\n  File \"/cluster/home/mmunso01/envs/nidaba/lib/python2.7/site-packages/redis/client.py\", line 2413, in immediate_execute_command\n    return self.parse_response(conn, command_name, **options)\n  File \"/cluster/home/mmunso01/envs/nidaba/lib/python2.7/site-packages/redis/client.py\", line 2536, in parse_response\n    self, connection, command_name, **options)\n  File \"/cluster/home/mmunso01/envs/nidaba/lib/python2.7/site-packages/redis/client.py\", line 577, in parse_response\n    response = connection.read_response()\n  File \"/cluster/home/mmunso01/envs/nidaba/lib/python2.7/site-packages/redis/connection.py\", line 574, in read_response\n    raise response\nResponseError: DISCARD without MULTI\n", "result": {"exc_message": "DISCARD without MULTI", "exc_type": "ResponseError"}, "children": []}) of pipeline caused error: MISCONF Redis is configured to save RDB snapshots, but is currently not able to persist on disk. Commands that may modify the data set are disabled. Please check Redis logs for details about the error.
[2015-10-16 09:24:53,560: WARNING/MainProcess] Restoring 4 unacknowledged message(s).
