[]
[1;36mcelery multi v3.1.18 (Cipater)[0m
> Starting nodes...
	> worker@alpha025: [1;32mOK[0m
tesseract grc+eng,extended=True /cluster/tufts/perseus_ocr/nidaba/Teubner/epicurus_1922 tif 3510 12
Fr 16. Okt 04:10:11 EDT 2015
Preparing filestore		[âœ“]
Building batch			[âœ“]
d6af2753-79ba-473a-a204-035a329ef067
Fr 16. Okt 05:12:10 EDT 2015
Traceback (most recent call last):
  File "/cluster/home/mmunso01/envs/nidaba/bin/nidaba", line 10, in <module>
    sys.exit(main())
  File "/cluster/home/mmunso01/envs/nidaba/lib/python2.7/site-packages/click/core.py", line 664, in __call__
    return self.main(*args, **kwargs)
  File "/cluster/home/mmunso01/envs/nidaba/lib/python2.7/site-packages/click/core.py", line 644, in main
    rv = self.invoke(ctx)
  File "/cluster/home/mmunso01/envs/nidaba/lib/python2.7/site-packages/click/core.py", line 991, in invoke
    return _process_result(sub_ctx.command.invoke(sub_ctx))
  File "/cluster/home/mmunso01/envs/nidaba/lib/python2.7/site-packages/click/core.py", line 837, in invoke
    return ctx.invoke(self.callback, **ctx.params)
  File "/cluster/home/mmunso01/envs/nidaba/lib/python2.7/site-packages/click/core.py", line 464, in invoke
    return callback(*args, **kwargs)
  File "/cluster/home/mmunso01/envs/nidaba/lib/python2.7/site-packages/nidaba/cli.py", line 284, in status
    state = batch.get_state()
  File "/cluster/home/mmunso01/envs/nidaba/lib/python2.7/site-packages/nidaba/nidaba.py", line 111, in get_state
    batch = r.get(self.id)
  File "/cluster/home/mmunso01/envs/nidaba/lib/python2.7/site-packages/redis/client.py", line 863, in get
    return self.execute_command('GET', name)
  File "/cluster/home/mmunso01/envs/nidaba/lib/python2.7/site-packages/redis/client.py", line 570, in execute_command
    connection.send_command(*args)
  File "/cluster/home/mmunso01/envs/nidaba/lib/python2.7/site-packages/redis/connection.py", line 556, in send_command
    self.send_packed_command(self.pack_command(*args))
  File "/cluster/home/mmunso01/envs/nidaba/lib/python2.7/site-packages/redis/connection.py", line 532, in send_packed_command
    self.connect()
  File "/cluster/home/mmunso01/envs/nidaba/lib/python2.7/site-packages/redis/connection.py", line 436, in connect
    raise ConnectionError(self._error_message(e))
redis.exceptions.ConnectionError: Error 111 connecting to 127.0.0.1:6379. Connection refused.
Traceback (most recent call last):
  File "/cluster/home/mmunso01/envs/nidaba/bin/nidaba", line 10, in <module>
    sys.exit(main())
  File "/cluster/home/mmunso01/envs/nidaba/lib/python2.7/site-packages/click/core.py", line 664, in __call__
    return self.main(*args, **kwargs)
  File "/cluster/home/mmunso01/envs/nidaba/lib/python2.7/site-packages/click/core.py", line 644, in main
    rv = self.invoke(ctx)
  File "/cluster/home/mmunso01/envs/nidaba/lib/python2.7/site-packages/click/core.py", line 991, in invoke
    return _process_result(sub_ctx.command.invoke(sub_ctx))
  File "/cluster/home/mmunso01/envs/nidaba/lib/python2.7/site-packages/click/core.py", line 837, in invoke
    return ctx.invoke(self.callback, **ctx.params)
  File "/cluster/home/mmunso01/envs/nidaba/lib/python2.7/site-packages/click/core.py", line 464, in invoke
    return callback(*args, **kwargs)
  File "/cluster/home/mmunso01/envs/nidaba/lib/python2.7/site-packages/nidaba/cli.py", line 284, in status
    state = batch.get_state()
  File "/cluster/home/mmunso01/envs/nidaba/lib/python2.7/site-packages/nidaba/nidaba.py", line 111, in get_state
    batch = r.get(self.id)
  File "/cluster/home/mmunso01/envs/nidaba/lib/python2.7/site-packages/redis/client.py", line 863, in get
    return self.execute_command('GET', name)
  File "/cluster/home/mmunso01/envs/nidaba/lib/python2.7/site-packages/redis/client.py", line 570, in execute_command
    connection.send_command(*args)
  File "/cluster/home/mmunso01/envs/nidaba/lib/python2.7/site-packages/redis/connection.py", line 556, in send_command
    self.send_packed_command(self.pack_command(*args))
  File "/cluster/home/mmunso01/envs/nidaba/lib/python2.7/site-packages/redis/connection.py", line 532, in send_packed_command
    self.connect()
  File "/cluster/home/mmunso01/envs/nidaba/lib/python2.7/site-packages/redis/connection.py", line 436, in connect
    raise ConnectionError(self._error_message(e))
redis.exceptions.ConnectionError: Error 111 connecting to 127.0.0.1:6379. Connection refused.
