[2015-10-16 01:10:29,567: WARNING/MainProcess] worker@omega011 ready.
[2015-10-16 01:13:42,751: ERROR/MainProcess] Task nidaba.ocr.tesseract[1d5db9de-2db7-4b36-a3f3-4c5658346339] raised unexpected: NidabaTesseractException(u'Tesseract killed by signal: 11',)
Traceback (most recent call last):
  File "/cluster/home/mmunso01/envs/nidaba/lib/python2.7/site-packages/celery/app/trace.py", line 240, in trace_task
    R = retval = fun(*args, **kwargs)
  File "/cluster/home/mmunso01/envs/nidaba/lib/python2.7/site-packages/nidaba/tasks/helper.py", line 87, in __call__
    ret = super(NidabaTask, self).__call__(*args, **nkwargs)
  File "/cluster/home/mmunso01/envs/nidaba/lib/python2.7/site-packages/celery/app/trace.py", line 438, in __protected_call__
    return self.run(*args, **kwargs)
  File "/cluster/home/mmunso01/envs/nidaba/lib/python2.7/site-packages/nidaba/plugins/tesseract.py", line 372, in ocr_tesseract
    ocr_capi(image_path, result_path, seg, languages, extended)
  File "/cluster/home/mmunso01/envs/nidaba/lib/python2.7/site-packages/nidaba/plugins/tesseract.py", line 420, in ocr_capi
    raise NidabaTesseractException('Tesseract killed by signal: {0}'.format(os.WTERMSIG(status)))
NidabaTesseractException: Tesseract killed by signal: 11
[2015-10-16 01:16:54,372: ERROR/MainProcess] Task nidaba.ocr.tesseract[e6598da0-6fc3-4885-9d8a-dbadb53558b0] raised unexpected: NidabaTesseractException(u'Tesseract killed by signal: 11',)
Traceback (most recent call last):
  File "/cluster/home/mmunso01/envs/nidaba/lib/python2.7/site-packages/celery/app/trace.py", line 240, in trace_task
    R = retval = fun(*args, **kwargs)
  File "/cluster/home/mmunso01/envs/nidaba/lib/python2.7/site-packages/nidaba/tasks/helper.py", line 87, in __call__
    ret = super(NidabaTask, self).__call__(*args, **nkwargs)
  File "/cluster/home/mmunso01/envs/nidaba/lib/python2.7/site-packages/celery/app/trace.py", line 438, in __protected_call__
    return self.run(*args, **kwargs)
  File "/cluster/home/mmunso01/envs/nidaba/lib/python2.7/site-packages/nidaba/plugins/tesseract.py", line 372, in ocr_tesseract
    ocr_capi(image_path, result_path, seg, languages, extended)
  File "/cluster/home/mmunso01/envs/nidaba/lib/python2.7/site-packages/nidaba/plugins/tesseract.py", line 420, in ocr_capi
    raise NidabaTesseractException('Tesseract killed by signal: {0}'.format(os.WTERMSIG(status)))
NidabaTesseractException: Tesseract killed by signal: 11
[2015-10-16 01:17:18,940: ERROR/MainProcess] Task nidaba.ocr.tesseract[fafa4925-29eb-4530-9759-d36f70d858de] raised unexpected: NidabaTesseractException(u'Tesseract killed by signal: 11',)
Traceback (most recent call last):
  File "/cluster/home/mmunso01/envs/nidaba/lib/python2.7/site-packages/celery/app/trace.py", line 240, in trace_task
    R = retval = fun(*args, **kwargs)
  File "/cluster/home/mmunso01/envs/nidaba/lib/python2.7/site-packages/nidaba/tasks/helper.py", line 87, in __call__
    ret = super(NidabaTask, self).__call__(*args, **nkwargs)
  File "/cluster/home/mmunso01/envs/nidaba/lib/python2.7/site-packages/celery/app/trace.py", line 438, in __protected_call__
    return self.run(*args, **kwargs)
  File "/cluster/home/mmunso01/envs/nidaba/lib/python2.7/site-packages/nidaba/plugins/tesseract.py", line 372, in ocr_tesseract
    ocr_capi(image_path, result_path, seg, languages, extended)
  File "/cluster/home/mmunso01/envs/nidaba/lib/python2.7/site-packages/nidaba/plugins/tesseract.py", line 420, in ocr_capi
    raise NidabaTesseractException('Tesseract killed by signal: {0}'.format(os.WTERMSIG(status)))
NidabaTesseractException: Tesseract killed by signal: 11
[2015-10-16 01:17:33,615: ERROR/MainProcess] Task nidaba.ocr.tesseract[c33a1ee1-5ee2-4624-ad59-e0ce34bd845b] raised unexpected: NidabaTesseractException(u'Tesseract killed by signal: 11',)
Traceback (most recent call last):
  File "/cluster/home/mmunso01/envs/nidaba/lib/python2.7/site-packages/celery/app/trace.py", line 240, in trace_task
    R = retval = fun(*args, **kwargs)
  File "/cluster/home/mmunso01/envs/nidaba/lib/python2.7/site-packages/nidaba/tasks/helper.py", line 87, in __call__
    ret = super(NidabaTask, self).__call__(*args, **nkwargs)
  File "/cluster/home/mmunso01/envs/nidaba/lib/python2.7/site-packages/celery/app/trace.py", line 438, in __protected_call__
    return self.run(*args, **kwargs)
  File "/cluster/home/mmunso01/envs/nidaba/lib/python2.7/site-packages/nidaba/plugins/tesseract.py", line 372, in ocr_tesseract
    ocr_capi(image_path, result_path, seg, languages, extended)
  File "/cluster/home/mmunso01/envs/nidaba/lib/python2.7/site-packages/nidaba/plugins/tesseract.py", line 420, in ocr_capi
    raise NidabaTesseractException('Tesseract killed by signal: {0}'.format(os.WTERMSIG(status)))
NidabaTesseractException: Tesseract killed by signal: 11
[2015-10-16 01:57:14,918: WARNING/MainProcess] consumer: Connection to broker lost. Trying to re-establish the connection...
Traceback (most recent call last):
  File "/cluster/home/mmunso01/envs/nidaba/lib/python2.7/site-packages/celery/worker/consumer.py", line 278, in start
    blueprint.start(self)
  File "/cluster/home/mmunso01/envs/nidaba/lib/python2.7/site-packages/celery/bootsteps.py", line 123, in start
    step.start(parent)
  File "/cluster/home/mmunso01/envs/nidaba/lib/python2.7/site-packages/celery/worker/consumer.py", line 821, in start
    c.loop(*c.loop_args())
  File "/cluster/home/mmunso01/envs/nidaba/lib/python2.7/site-packages/celery/worker/loops.py", line 70, in asynloop
    next(loop)
  File "/cluster/home/mmunso01/envs/nidaba/lib/python2.7/site-packages/kombu/async/hub.py", line 267, in create_loop
    tick_callback()
  File "/cluster/home/mmunso01/envs/nidaba/lib/python2.7/site-packages/kombu/transport/redis.py", line 943, in on_poll_start
    cycle_poll_start()
  File "/cluster/home/mmunso01/envs/nidaba/lib/python2.7/site-packages/kombu/transport/redis.py", line 300, in on_poll_start
    self._register_BRPOP(channel)
  File "/cluster/home/mmunso01/envs/nidaba/lib/python2.7/site-packages/kombu/transport/redis.py", line 283, in _register_BRPOP
    self._register(*ident)
  File "/cluster/home/mmunso01/envs/nidaba/lib/python2.7/site-packages/kombu/transport/redis.py", line 268, in _register
    client.connection.connect()
  File "/cluster/home/mmunso01/envs/nidaba/lib/python2.7/site-packages/redis/connection.py", line 436, in connect
    raise ConnectionError(self._error_message(e))
ConnectionError: Error 111 connecting to 127.0.0.1:6379. Connection refused.
[2015-10-16 01:57:14,938: ERROR/MainProcess] consumer: Cannot connect to redis://127.0.0.1:6379//: Error 111 connecting to 127.0.0.1:6379. Connection refused..
Trying again in 2.00 seconds...

[2015-10-16 01:57:16,942: ERROR/MainProcess] consumer: Cannot connect to redis://127.0.0.1:6379//: Error 111 connecting to 127.0.0.1:6379. Connection refused..
Trying again in 4.00 seconds...

[2015-10-16 01:57:20,949: ERROR/MainProcess] consumer: Cannot connect to redis://127.0.0.1:6379//: Error 111 connecting to 127.0.0.1:6379. Connection refused..
Trying again in 6.00 seconds...

[2015-10-16 01:57:26,959: ERROR/MainProcess] consumer: Cannot connect to redis://127.0.0.1:6379//: Error 111 connecting to 127.0.0.1:6379. Connection refused..
Trying again in 8.00 seconds...

